[2022-06-30 17:04:18,941] {taskinstance.py:1032} INFO - Dependencies all met for <TaskInstance: data_adjusted.format_to_csv_task manual__2022-06-30T16:51:16.374227+00:00 [queued]>
[2022-06-30 17:04:18,954] {taskinstance.py:1032} INFO - Dependencies all met for <TaskInstance: data_adjusted.format_to_csv_task manual__2022-06-30T16:51:16.374227+00:00 [queued]>
[2022-06-30 17:04:18,955] {taskinstance.py:1238} INFO - 
--------------------------------------------------------------------------------
[2022-06-30 17:04:18,955] {taskinstance.py:1239} INFO - Starting attempt 2 of 2
[2022-06-30 17:04:18,955] {taskinstance.py:1240} INFO - 
--------------------------------------------------------------------------------
[2022-06-30 17:04:18,971] {taskinstance.py:1259} INFO - Executing <Task(PythonOperator): format_to_csv_task> on 2022-06-30 16:51:16.374227+00:00
[2022-06-30 17:04:18,977] {standard_task_runner.py:52} INFO - Started process 4190 to run task
[2022-06-30 17:04:18,982] {standard_task_runner.py:76} INFO - Running: ['***', 'tasks', 'run', 'data_adjusted', 'format_to_csv_task', 'manual__2022-06-30T16:51:16.374227+00:00', '--job-id', '25', '--raw', '--subdir', 'DAGS_FOLDER/data_adjusted.py', '--cfg-path', '/tmp/tmp4tlstrqi', '--error-file', '/tmp/tmpxw0k9abe']
[2022-06-30 17:04:18,983] {standard_task_runner.py:77} INFO - Job 25: Subtask format_to_csv_task
[2022-06-30 17:04:19,046] {logging_mixin.py:109} INFO - Running <TaskInstance: data_adjusted.format_to_csv_task manual__2022-06-30T16:51:16.374227+00:00 [running]> on host d4c453d82639
[2022-06-30 17:04:19,112] {taskinstance.py:1426} INFO - Exporting the following env vars:
AIRFLOW_CTX_DAG_OWNER=***
AIRFLOW_CTX_DAG_ID=data_adjusted
AIRFLOW_CTX_TASK_ID=format_to_csv_task
AIRFLOW_CTX_EXECUTION_DATE=2022-06-30T16:51:16.374227+00:00
AIRFLOW_CTX_DAG_RUN_ID=manual__2022-06-30T16:51:16.374227+00:00
[2022-06-30 17:04:19,481] {taskinstance.py:1700} ERROR - Task failed with exception
Traceback (most recent call last):
  File "/home/airflow/.local/lib/python3.7/site-packages/airflow/models/taskinstance.py", line 1329, in _run_raw_task
    self._execute_task_with_callbacks(context)
  File "/home/airflow/.local/lib/python3.7/site-packages/airflow/models/taskinstance.py", line 1455, in _execute_task_with_callbacks
    result = self._execute_task(context, self.task)
  File "/home/airflow/.local/lib/python3.7/site-packages/airflow/models/taskinstance.py", line 1511, in _execute_task
    result = execute_callable(context=context)
  File "/home/airflow/.local/lib/python3.7/site-packages/airflow/operators/python.py", line 174, in execute
    return_value = self.execute_callable()
  File "/home/airflow/.local/lib/python3.7/site-packages/airflow/operators/python.py", line 185, in execute_callable
    return self.python_callable(*self.op_args, **self.op_kwargs)
  File "/opt/airflow/dags/data_adjusted.py", line 31, in format_to_csv
    pd.write_csv(table, src_file)
  File "/home/airflow/.local/lib/python3.7/site-packages/pandas/__init__.py", line 244, in __getattr__
    raise AttributeError(f"module 'pandas' has no attribute '{name}'")
AttributeError: module 'pandas' has no attribute 'write_csv'
[2022-06-30 17:04:19,499] {taskinstance.py:1277} INFO - Marking task as FAILED. dag_id=data_adjusted, task_id=format_to_csv_task, execution_date=20220630T165116, start_date=20220630T170418, end_date=20220630T170419
[2022-06-30 17:04:19,518] {standard_task_runner.py:92} ERROR - Failed to execute job 25 for task format_to_csv_task
Traceback (most recent call last):
  File "/home/airflow/.local/lib/python3.7/site-packages/airflow/task/task_runner/standard_task_runner.py", line 85, in _start_by_fork
    args.func(args, dag=self.dag)
  File "/home/airflow/.local/lib/python3.7/site-packages/airflow/cli/cli_parser.py", line 48, in command
    return func(*args, **kwargs)
  File "/home/airflow/.local/lib/python3.7/site-packages/airflow/utils/cli.py", line 92, in wrapper
    return f(*args, **kwargs)
  File "/home/airflow/.local/lib/python3.7/site-packages/airflow/cli/commands/task_command.py", line 298, in task_run
    _run_task_by_selected_method(args, dag, ti)
  File "/home/airflow/.local/lib/python3.7/site-packages/airflow/cli/commands/task_command.py", line 107, in _run_task_by_selected_method
    _run_raw_task(args, ti)
  File "/home/airflow/.local/lib/python3.7/site-packages/airflow/cli/commands/task_command.py", line 184, in _run_raw_task
    error_file=args.error_file,
  File "/home/airflow/.local/lib/python3.7/site-packages/airflow/utils/session.py", line 70, in wrapper
    return func(*args, session=session, **kwargs)
  File "/home/airflow/.local/lib/python3.7/site-packages/airflow/models/taskinstance.py", line 1329, in _run_raw_task
    self._execute_task_with_callbacks(context)
  File "/home/airflow/.local/lib/python3.7/site-packages/airflow/models/taskinstance.py", line 1455, in _execute_task_with_callbacks
    result = self._execute_task(context, self.task)
  File "/home/airflow/.local/lib/python3.7/site-packages/airflow/models/taskinstance.py", line 1511, in _execute_task
    result = execute_callable(context=context)
  File "/home/airflow/.local/lib/python3.7/site-packages/airflow/operators/python.py", line 174, in execute
    return_value = self.execute_callable()
  File "/home/airflow/.local/lib/python3.7/site-packages/airflow/operators/python.py", line 185, in execute_callable
    return self.python_callable(*self.op_args, **self.op_kwargs)
  File "/opt/airflow/dags/data_adjusted.py", line 31, in format_to_csv
    pd.write_csv(table, src_file)
  File "/home/airflow/.local/lib/python3.7/site-packages/pandas/__init__.py", line 244, in __getattr__
    raise AttributeError(f"module 'pandas' has no attribute '{name}'")
AttributeError: module 'pandas' has no attribute 'write_csv'
[2022-06-30 17:04:19,555] {local_task_job.py:154} INFO - Task exited with return code 1
[2022-06-30 17:04:19,600] {local_task_job.py:264} INFO - 0 downstream tasks scheduled from follow-on schedule check
