[2022-06-30 16:59:10,335] {taskinstance.py:1032} INFO - Dependencies all met for <TaskInstance: data_adjusted.format_to_csv_task manual__2022-06-30T16:46:56.894007+00:00 [queued]>
[2022-06-30 16:59:10,347] {taskinstance.py:1032} INFO - Dependencies all met for <TaskInstance: data_adjusted.format_to_csv_task manual__2022-06-30T16:46:56.894007+00:00 [queued]>
[2022-06-30 16:59:10,347] {taskinstance.py:1238} INFO - 
--------------------------------------------------------------------------------
[2022-06-30 16:59:10,348] {taskinstance.py:1239} INFO - Starting attempt 4 of 4
[2022-06-30 16:59:10,348] {taskinstance.py:1240} INFO - 
--------------------------------------------------------------------------------
[2022-06-30 16:59:10,363] {taskinstance.py:1259} INFO - Executing <Task(PythonOperator): format_to_csv_task> on 2022-06-30 16:46:56.894007+00:00
[2022-06-30 16:59:10,369] {standard_task_runner.py:52} INFO - Started process 3761 to run task
[2022-06-30 16:59:10,374] {standard_task_runner.py:76} INFO - Running: ['***', 'tasks', 'run', 'data_adjusted', 'format_to_csv_task', 'manual__2022-06-30T16:46:56.894007+00:00', '--job-id', '22', '--raw', '--subdir', 'DAGS_FOLDER/data_adjusted.py', '--cfg-path', '/tmp/tmpzkdukq6_', '--error-file', '/tmp/tmp7liphcqw']
[2022-06-30 16:59:10,375] {standard_task_runner.py:77} INFO - Job 22: Subtask format_to_csv_task
[2022-06-30 16:59:10,442] {logging_mixin.py:109} INFO - Running <TaskInstance: data_adjusted.format_to_csv_task manual__2022-06-30T16:46:56.894007+00:00 [running]> on host d4c453d82639
[2022-06-30 16:59:10,503] {taskinstance.py:1426} INFO - Exporting the following env vars:
AIRFLOW_CTX_DAG_OWNER=***
AIRFLOW_CTX_DAG_ID=data_adjusted
AIRFLOW_CTX_TASK_ID=format_to_csv_task
AIRFLOW_CTX_EXECUTION_DATE=2022-06-30T16:46:56.894007+00:00
AIRFLOW_CTX_DAG_RUN_ID=manual__2022-06-30T16:46:56.894007+00:00
[2022-06-30 16:59:10,519] {taskinstance.py:1700} ERROR - Task failed with exception
Traceback (most recent call last):
  File "/home/airflow/.local/lib/python3.7/site-packages/airflow/models/taskinstance.py", line 1329, in _run_raw_task
    self._execute_task_with_callbacks(context)
  File "/home/airflow/.local/lib/python3.7/site-packages/airflow/models/taskinstance.py", line 1455, in _execute_task_with_callbacks
    result = self._execute_task(context, self.task)
  File "/home/airflow/.local/lib/python3.7/site-packages/airflow/models/taskinstance.py", line 1511, in _execute_task
    result = execute_callable(context=context)
  File "/home/airflow/.local/lib/python3.7/site-packages/airflow/operators/python.py", line 174, in execute
    return_value = self.execute_callable()
  File "/home/airflow/.local/lib/python3.7/site-packages/airflow/operators/python.py", line 185, in execute_callable
    return self.python_callable(*self.op_args, **self.op_kwargs)
  File "/opt/airflow/dags/data_adjusted.py", line 30, in format_to_csv
    table =pd.read_parquet(src_file,engine='pyarrow')
  File "/home/airflow/.local/lib/python3.7/site-packages/pandas/io/parquet.py", line 500, in read_parquet
    **kwargs,
  File "/home/airflow/.local/lib/python3.7/site-packages/pandas/io/parquet.py", line 240, in read
    path_or_handle, columns=columns, **kwargs
  File "/home/airflow/.local/lib/python3.7/site-packages/pyarrow/parquet.py", line 1869, in read_table
    coerce_int96_timestamp_unit=coerce_int96_timestamp_unit
  File "/home/airflow/.local/lib/python3.7/site-packages/pyarrow/parquet.py", line 1679, in __init__
    [fragment], schema=fragment.physical_schema,
  File "pyarrow/_dataset.pyx", line 952, in pyarrow._dataset.Fragment.physical_schema.__get__
  File "pyarrow/error.pxi", line 143, in pyarrow.lib.pyarrow_internal_check_status
  File "pyarrow/error.pxi", line 99, in pyarrow.lib.check_status
pyarrow.lib.ArrowInvalid: Could not open Parquet input source '<Buffer>': Parquet magic bytes not found in footer. Either the file is corrupted or this is not a parquet file.
[2022-06-30 16:59:10,534] {taskinstance.py:1277} INFO - Marking task as FAILED. dag_id=data_adjusted, task_id=format_to_csv_task, execution_date=20220630T164656, start_date=20220630T165910, end_date=20220630T165910
[2022-06-30 16:59:10,550] {standard_task_runner.py:92} ERROR - Failed to execute job 22 for task format_to_csv_task
Traceback (most recent call last):
  File "/home/airflow/.local/lib/python3.7/site-packages/airflow/task/task_runner/standard_task_runner.py", line 85, in _start_by_fork
    args.func(args, dag=self.dag)
  File "/home/airflow/.local/lib/python3.7/site-packages/airflow/cli/cli_parser.py", line 48, in command
    return func(*args, **kwargs)
  File "/home/airflow/.local/lib/python3.7/site-packages/airflow/utils/cli.py", line 92, in wrapper
    return f(*args, **kwargs)
  File "/home/airflow/.local/lib/python3.7/site-packages/airflow/cli/commands/task_command.py", line 298, in task_run
    _run_task_by_selected_method(args, dag, ti)
  File "/home/airflow/.local/lib/python3.7/site-packages/airflow/cli/commands/task_command.py", line 107, in _run_task_by_selected_method
    _run_raw_task(args, ti)
  File "/home/airflow/.local/lib/python3.7/site-packages/airflow/cli/commands/task_command.py", line 184, in _run_raw_task
    error_file=args.error_file,
  File "/home/airflow/.local/lib/python3.7/site-packages/airflow/utils/session.py", line 70, in wrapper
    return func(*args, session=session, **kwargs)
  File "/home/airflow/.local/lib/python3.7/site-packages/airflow/models/taskinstance.py", line 1329, in _run_raw_task
    self._execute_task_with_callbacks(context)
  File "/home/airflow/.local/lib/python3.7/site-packages/airflow/models/taskinstance.py", line 1455, in _execute_task_with_callbacks
    result = self._execute_task(context, self.task)
  File "/home/airflow/.local/lib/python3.7/site-packages/airflow/models/taskinstance.py", line 1511, in _execute_task
    result = execute_callable(context=context)
  File "/home/airflow/.local/lib/python3.7/site-packages/airflow/operators/python.py", line 174, in execute
    return_value = self.execute_callable()
  File "/home/airflow/.local/lib/python3.7/site-packages/airflow/operators/python.py", line 185, in execute_callable
    return self.python_callable(*self.op_args, **self.op_kwargs)
  File "/opt/airflow/dags/data_adjusted.py", line 30, in format_to_csv
    table =pd.read_parquet(src_file,engine='pyarrow')
  File "/home/airflow/.local/lib/python3.7/site-packages/pandas/io/parquet.py", line 500, in read_parquet
    **kwargs,
  File "/home/airflow/.local/lib/python3.7/site-packages/pandas/io/parquet.py", line 240, in read
    path_or_handle, columns=columns, **kwargs
  File "/home/airflow/.local/lib/python3.7/site-packages/pyarrow/parquet.py", line 1869, in read_table
    coerce_int96_timestamp_unit=coerce_int96_timestamp_unit
  File "/home/airflow/.local/lib/python3.7/site-packages/pyarrow/parquet.py", line 1679, in __init__
    [fragment], schema=fragment.physical_schema,
  File "pyarrow/_dataset.pyx", line 952, in pyarrow._dataset.Fragment.physical_schema.__get__
  File "pyarrow/error.pxi", line 143, in pyarrow.lib.pyarrow_internal_check_status
  File "pyarrow/error.pxi", line 99, in pyarrow.lib.check_status
pyarrow.lib.ArrowInvalid: Could not open Parquet input source '<Buffer>': Parquet magic bytes not found in footer. Either the file is corrupted or this is not a parquet file.
[2022-06-30 16:59:10,586] {local_task_job.py:154} INFO - Task exited with return code 1
[2022-06-30 16:59:10,630] {local_task_job.py:264} INFO - 0 downstream tasks scheduled from follow-on schedule check
