[2022-06-30 16:30:46,264] {taskinstance.py:1032} INFO - Dependencies all met for <TaskInstance: data_adjusted.format_to_csv_task scheduled__2022-06-29T00:00:00+00:00 [queued]>
[2022-06-30 16:30:46,277] {taskinstance.py:1032} INFO - Dependencies all met for <TaskInstance: data_adjusted.format_to_csv_task scheduled__2022-06-29T00:00:00+00:00 [queued]>
[2022-06-30 16:30:46,277] {taskinstance.py:1238} INFO - 
--------------------------------------------------------------------------------
[2022-06-30 16:30:46,277] {taskinstance.py:1239} INFO - Starting attempt 2 of 2
[2022-06-30 16:30:46,277] {taskinstance.py:1240} INFO - 
--------------------------------------------------------------------------------
[2022-06-30 16:30:46,292] {taskinstance.py:1259} INFO - Executing <Task(PythonOperator): format_to_csv_task> on 2022-06-29 00:00:00+00:00
[2022-06-30 16:30:46,298] {standard_task_runner.py:52} INFO - Started process 1389 to run task
[2022-06-30 16:30:46,303] {standard_task_runner.py:76} INFO - Running: ['***', 'tasks', 'run', 'data_adjusted', 'format_to_csv_task', 'scheduled__2022-06-29T00:00:00+00:00', '--job-id', '11', '--raw', '--subdir', 'DAGS_FOLDER/data_adjusted.py', '--cfg-path', '/tmp/tmpiqsmf5mq', '--error-file', '/tmp/tmp4fhbov5q']
[2022-06-30 16:30:46,305] {standard_task_runner.py:77} INFO - Job 11: Subtask format_to_csv_task
[2022-06-30 16:30:46,378] {logging_mixin.py:109} INFO - Running <TaskInstance: data_adjusted.format_to_csv_task scheduled__2022-06-29T00:00:00+00:00 [running]> on host d4c453d82639
[2022-06-30 16:30:46,453] {taskinstance.py:1426} INFO - Exporting the following env vars:
AIRFLOW_CTX_DAG_OWNER=***
AIRFLOW_CTX_DAG_ID=data_adjusted
AIRFLOW_CTX_TASK_ID=format_to_csv_task
AIRFLOW_CTX_EXECUTION_DATE=2022-06-29T00:00:00+00:00
AIRFLOW_CTX_DAG_RUN_ID=scheduled__2022-06-29T00:00:00+00:00
[2022-06-30 16:30:46,929] {taskinstance.py:1700} ERROR - Task failed with exception
Traceback (most recent call last):
  File "/home/airflow/.local/lib/python3.7/site-packages/airflow/models/taskinstance.py", line 1329, in _run_raw_task
    self._execute_task_with_callbacks(context)
  File "/home/airflow/.local/lib/python3.7/site-packages/airflow/models/taskinstance.py", line 1455, in _execute_task_with_callbacks
    result = self._execute_task(context, self.task)
  File "/home/airflow/.local/lib/python3.7/site-packages/airflow/models/taskinstance.py", line 1511, in _execute_task
    result = execute_callable(context=context)
  File "/home/airflow/.local/lib/python3.7/site-packages/airflow/operators/python.py", line 174, in execute
    return_value = self.execute_callable()
  File "/home/airflow/.local/lib/python3.7/site-packages/airflow/operators/python.py", line 185, in execute_callable
    return self.python_callable(*self.op_args, **self.op_kwargs)
  File "/opt/airflow/dags/data_adjusted.py", line 30, in format_to_csv
    pv.write_csv(table, src_file.replace('.parquet', '.csv'))
  File "pyarrow/_csv.pyx", line 1025, in pyarrow._csv.write_csv
  File "pyarrow/error.pxi", line 120, in pyarrow.lib.check_status
pyarrow.lib.ArrowNotImplementedError: Unsupported cast from timestamp[us] to utf8 using function cast_string
[2022-06-30 16:30:46,950] {taskinstance.py:1277} INFO - Marking task as FAILED. dag_id=data_adjusted, task_id=format_to_csv_task, execution_date=20220629T000000, start_date=20220630T163046, end_date=20220630T163046
[2022-06-30 16:30:46,968] {standard_task_runner.py:92} ERROR - Failed to execute job 11 for task format_to_csv_task
Traceback (most recent call last):
  File "/home/airflow/.local/lib/python3.7/site-packages/airflow/task/task_runner/standard_task_runner.py", line 85, in _start_by_fork
    args.func(args, dag=self.dag)
  File "/home/airflow/.local/lib/python3.7/site-packages/airflow/cli/cli_parser.py", line 48, in command
    return func(*args, **kwargs)
  File "/home/airflow/.local/lib/python3.7/site-packages/airflow/utils/cli.py", line 92, in wrapper
    return f(*args, **kwargs)
  File "/home/airflow/.local/lib/python3.7/site-packages/airflow/cli/commands/task_command.py", line 298, in task_run
    _run_task_by_selected_method(args, dag, ti)
  File "/home/airflow/.local/lib/python3.7/site-packages/airflow/cli/commands/task_command.py", line 107, in _run_task_by_selected_method
    _run_raw_task(args, ti)
  File "/home/airflow/.local/lib/python3.7/site-packages/airflow/cli/commands/task_command.py", line 184, in _run_raw_task
    error_file=args.error_file,
  File "/home/airflow/.local/lib/python3.7/site-packages/airflow/utils/session.py", line 70, in wrapper
    return func(*args, session=session, **kwargs)
  File "/home/airflow/.local/lib/python3.7/site-packages/airflow/models/taskinstance.py", line 1329, in _run_raw_task
    self._execute_task_with_callbacks(context)
  File "/home/airflow/.local/lib/python3.7/site-packages/airflow/models/taskinstance.py", line 1455, in _execute_task_with_callbacks
    result = self._execute_task(context, self.task)
  File "/home/airflow/.local/lib/python3.7/site-packages/airflow/models/taskinstance.py", line 1511, in _execute_task
    result = execute_callable(context=context)
  File "/home/airflow/.local/lib/python3.7/site-packages/airflow/operators/python.py", line 174, in execute
    return_value = self.execute_callable()
  File "/home/airflow/.local/lib/python3.7/site-packages/airflow/operators/python.py", line 185, in execute_callable
    return self.python_callable(*self.op_args, **self.op_kwargs)
  File "/opt/airflow/dags/data_adjusted.py", line 30, in format_to_csv
    pv.write_csv(table, src_file.replace('.parquet', '.csv'))
  File "pyarrow/_csv.pyx", line 1025, in pyarrow._csv.write_csv
  File "pyarrow/error.pxi", line 120, in pyarrow.lib.check_status
pyarrow.lib.ArrowNotImplementedError: Unsupported cast from timestamp[us] to utf8 using function cast_string
[2022-06-30 16:30:47,003] {local_task_job.py:154} INFO - Task exited with return code 1
[2022-06-30 16:30:47,050] {local_task_job.py:264} INFO - 0 downstream tasks scheduled from follow-on schedule check
