[2022-07-07 15:25:49,587] {taskinstance.py:1032} INFO - Dependencies all met for <TaskInstance: LocalIngestionDag.convert_to_csv manual__2022-07-07T15:25:09.754638+00:00 [queued]>
[2022-07-07 15:25:49,626] {taskinstance.py:1032} INFO - Dependencies all met for <TaskInstance: LocalIngestionDag.convert_to_csv manual__2022-07-07T15:25:09.754638+00:00 [queued]>
[2022-07-07 15:25:49,627] {taskinstance.py:1238} INFO - 
--------------------------------------------------------------------------------
[2022-07-07 15:25:49,627] {taskinstance.py:1239} INFO - Starting attempt 1 of 1
[2022-07-07 15:25:49,627] {taskinstance.py:1240} INFO - 
--------------------------------------------------------------------------------
[2022-07-07 15:25:49,656] {taskinstance.py:1259} INFO - Executing <Task(PythonOperator): convert_to_csv> on 2022-07-07 15:25:09.754638+00:00
[2022-07-07 15:25:49,664] {standard_task_runner.py:52} INFO - Started process 1017 to run task
[2022-07-07 15:25:49,684] {standard_task_runner.py:76} INFO - Running: ['***', 'tasks', 'run', 'LocalIngestionDag', 'convert_to_csv', 'manual__2022-07-07T15:25:09.754638+00:00', '--job-id', '154', '--raw', '--subdir', 'DAGS_FOLDER/data_ingestion_local.py', '--cfg-path', '/tmp/tmpq1ybngiw', '--error-file', '/tmp/tmpo2ovk8m6']
[2022-07-07 15:25:49,694] {standard_task_runner.py:77} INFO - Job 154: Subtask convert_to_csv
[2022-07-07 15:25:49,819] {logging_mixin.py:109} INFO - Running <TaskInstance: LocalIngestionDag.convert_to_csv manual__2022-07-07T15:25:09.754638+00:00 [running]> on host d7995de6702f
[2022-07-07 15:25:49,922] {warnings.py:110} WARNING - /home/***/.local/lib/python3.7/site-packages/***/utils/context.py:152: AirflowContextDeprecationWarning: Accessing 'execution_date' from the template is deprecated and will be removed in a future version. Please use 'data_interval_start' or 'logical_date' instead.
  warnings.warn(_create_deprecation_warning(key, self._deprecation_replacements[key]))

[2022-07-07 15:25:49,983] {taskinstance.py:1426} INFO - Exporting the following env vars:
AIRFLOW_CTX_DAG_OWNER=***
AIRFLOW_CTX_DAG_ID=LocalIngestionDag
AIRFLOW_CTX_TASK_ID=convert_to_csv
AIRFLOW_CTX_EXECUTION_DATE=2022-07-07T15:25:09.754638+00:00
AIRFLOW_CTX_DAG_RUN_ID=manual__2022-07-07T15:25:09.754638+00:00
[2022-07-07 15:25:50,030] {taskinstance.py:1700} ERROR - Task failed with exception
Traceback (most recent call last):
  File "/home/airflow/.local/lib/python3.7/site-packages/airflow/models/taskinstance.py", line 1329, in _run_raw_task
    self._execute_task_with_callbacks(context)
  File "/home/airflow/.local/lib/python3.7/site-packages/airflow/models/taskinstance.py", line 1455, in _execute_task_with_callbacks
    result = self._execute_task(context, self.task)
  File "/home/airflow/.local/lib/python3.7/site-packages/airflow/models/taskinstance.py", line 1511, in _execute_task
    result = execute_callable(context=context)
  File "/home/airflow/.local/lib/python3.7/site-packages/airflow/operators/python.py", line 174, in execute
    return_value = self.execute_callable()
  File "/home/airflow/.local/lib/python3.7/site-packages/airflow/operators/python.py", line 185, in execute_callable
    return self.python_callable(*self.op_args, **self.op_kwargs)
  File "/opt/airflow/dags/ingest_script.py", line 14, in format_to_csv
    table = pq.read_table(src_file)
  File "/home/airflow/.local/lib/python3.7/site-packages/pyarrow/parquet.py", line 1869, in read_table
    coerce_int96_timestamp_unit=coerce_int96_timestamp_unit
  File "/home/airflow/.local/lib/python3.7/site-packages/pyarrow/parquet.py", line 1679, in __init__
    [fragment], schema=fragment.physical_schema,
  File "pyarrow/_dataset.pyx", line 952, in pyarrow._dataset.Fragment.physical_schema.__get__
  File "pyarrow/error.pxi", line 143, in pyarrow.lib.pyarrow_internal_check_status
  File "pyarrow/error.pxi", line 99, in pyarrow.lib.check_status
pyarrow.lib.ArrowInvalid: Could not open Parquet input source '/opt/***/output_2022-07.parquet': Parquet magic bytes not found in footer. Either the file is corrupted or this is not a parquet file.
[2022-07-07 15:25:50,062] {taskinstance.py:1277} INFO - Marking task as FAILED. dag_id=LocalIngestionDag, task_id=convert_to_csv, execution_date=20220707T152509, start_date=20220707T152549, end_date=20220707T152550
[2022-07-07 15:25:50,086] {standard_task_runner.py:92} ERROR - Failed to execute job 154 for task convert_to_csv
Traceback (most recent call last):
  File "/home/airflow/.local/lib/python3.7/site-packages/airflow/task/task_runner/standard_task_runner.py", line 85, in _start_by_fork
    args.func(args, dag=self.dag)
  File "/home/airflow/.local/lib/python3.7/site-packages/airflow/cli/cli_parser.py", line 48, in command
    return func(*args, **kwargs)
  File "/home/airflow/.local/lib/python3.7/site-packages/airflow/utils/cli.py", line 92, in wrapper
    return f(*args, **kwargs)
  File "/home/airflow/.local/lib/python3.7/site-packages/airflow/cli/commands/task_command.py", line 298, in task_run
    _run_task_by_selected_method(args, dag, ti)
  File "/home/airflow/.local/lib/python3.7/site-packages/airflow/cli/commands/task_command.py", line 107, in _run_task_by_selected_method
    _run_raw_task(args, ti)
  File "/home/airflow/.local/lib/python3.7/site-packages/airflow/cli/commands/task_command.py", line 184, in _run_raw_task
    error_file=args.error_file,
  File "/home/airflow/.local/lib/python3.7/site-packages/airflow/utils/session.py", line 70, in wrapper
    return func(*args, session=session, **kwargs)
  File "/home/airflow/.local/lib/python3.7/site-packages/airflow/models/taskinstance.py", line 1329, in _run_raw_task
    self._execute_task_with_callbacks(context)
  File "/home/airflow/.local/lib/python3.7/site-packages/airflow/models/taskinstance.py", line 1455, in _execute_task_with_callbacks
    result = self._execute_task(context, self.task)
  File "/home/airflow/.local/lib/python3.7/site-packages/airflow/models/taskinstance.py", line 1511, in _execute_task
    result = execute_callable(context=context)
  File "/home/airflow/.local/lib/python3.7/site-packages/airflow/operators/python.py", line 174, in execute
    return_value = self.execute_callable()
  File "/home/airflow/.local/lib/python3.7/site-packages/airflow/operators/python.py", line 185, in execute_callable
    return self.python_callable(*self.op_args, **self.op_kwargs)
  File "/opt/airflow/dags/ingest_script.py", line 14, in format_to_csv
    table = pq.read_table(src_file)
  File "/home/airflow/.local/lib/python3.7/site-packages/pyarrow/parquet.py", line 1869, in read_table
    coerce_int96_timestamp_unit=coerce_int96_timestamp_unit
  File "/home/airflow/.local/lib/python3.7/site-packages/pyarrow/parquet.py", line 1679, in __init__
    [fragment], schema=fragment.physical_schema,
  File "pyarrow/_dataset.pyx", line 952, in pyarrow._dataset.Fragment.physical_schema.__get__
  File "pyarrow/error.pxi", line 143, in pyarrow.lib.pyarrow_internal_check_status
  File "pyarrow/error.pxi", line 99, in pyarrow.lib.check_status
pyarrow.lib.ArrowInvalid: Could not open Parquet input source '/opt/***/output_2022-07.parquet': Parquet magic bytes not found in footer. Either the file is corrupted or this is not a parquet file.
[2022-07-07 15:25:50,147] {local_task_job.py:154} INFO - Task exited with return code 1
[2022-07-07 15:25:50,243] {local_task_job.py:264} INFO - 0 downstream tasks scheduled from follow-on schedule check
[2022-07-07 15:25:50,288] {dagrun.py:530} ERROR - Marking run <DagRun LocalIngestionDag @ 2022-07-07 15:25:09.754638+00:00: manual__2022-07-07T15:25:09.754638+00:00, externally triggered: True> failed
[2022-07-07 15:25:50,289] {dagrun.py:605} INFO - DagRun Finished: dag_id=LocalIngestionDag, execution_date=2022-07-07 15:25:09.754638+00:00, run_id=manual__2022-07-07T15:25:09.754638+00:00, run_start_date=2022-07-07 15:25:33.008802+00:00, run_end_date=2022-07-07 15:25:50.288925+00:00, run_duration=17.280123, state=failed, external_trigger=True, run_type=manual, data_interval_start=2022-06-02 06:00:00+00:00, data_interval_end=2022-07-02 06:00:00+00:00, dag_hash=1e3401df9957ffbe169822215ae1dad9
