[2022-07-07 18:10:15,155] {taskinstance.py:1032} INFO - Dependencies all met for <TaskInstance: LocalIngestionDag.ingest scheduled__2021-03-02T06:00:00+00:00 [queued]>
[2022-07-07 18:10:15,173] {taskinstance.py:1032} INFO - Dependencies all met for <TaskInstance: LocalIngestionDag.ingest scheduled__2021-03-02T06:00:00+00:00 [queued]>
[2022-07-07 18:10:15,173] {taskinstance.py:1238} INFO - 
--------------------------------------------------------------------------------
[2022-07-07 18:10:15,174] {taskinstance.py:1239} INFO - Starting attempt 11 of 11
[2022-07-07 18:10:15,174] {taskinstance.py:1240} INFO - 
--------------------------------------------------------------------------------
[2022-07-07 18:10:15,191] {taskinstance.py:1259} INFO - Executing <Task(PythonOperator): ingest> on 2021-03-02 06:00:00+00:00
[2022-07-07 18:10:15,199] {standard_task_runner.py:52} INFO - Started process 1820 to run task
[2022-07-07 18:10:15,204] {standard_task_runner.py:76} INFO - Running: ['***', 'tasks', 'run', 'LocalIngestionDag', 'ingest', 'scheduled__2021-03-02T06:00:00+00:00', '--job-id', '192', '--raw', '--subdir', 'DAGS_FOLDER/data_ingestion_local.py', '--cfg-path', '/tmp/tmpqmep1h2u', '--error-file', '/tmp/tmp8yo5qa3q']
[2022-07-07 18:10:15,205] {standard_task_runner.py:77} INFO - Job 192: Subtask ingest
[2022-07-07 18:10:15,274] {logging_mixin.py:109} INFO - Running <TaskInstance: LocalIngestionDag.ingest scheduled__2021-03-02T06:00:00+00:00 [running]> on host d7995de6702f
[2022-07-07 18:10:15,321] {warnings.py:110} WARNING - /home/***/.local/lib/python3.7/site-packages/***/utils/context.py:152: AirflowContextDeprecationWarning: Accessing 'execution_date' from the template is deprecated and will be removed in a future version. Please use 'data_interval_start' or 'logical_date' instead.
  warnings.warn(_create_deprecation_warning(key, self._deprecation_replacements[key]))

[2022-07-07 18:10:15,343] {taskinstance.py:1426} INFO - Exporting the following env vars:
AIRFLOW_CTX_DAG_OWNER=***
AIRFLOW_CTX_DAG_ID=LocalIngestionDag
AIRFLOW_CTX_TASK_ID=ingest
AIRFLOW_CTX_EXECUTION_DATE=2021-03-02T06:00:00+00:00
AIRFLOW_CTX_DAG_RUN_ID=scheduled__2021-03-02T06:00:00+00:00
[2022-07-07 18:10:15,345] {taskinstance.py:1700} ERROR - Task failed with exception
Traceback (most recent call last):
  File "/home/airflow/.local/lib/python3.7/site-packages/airflow/models/taskinstance.py", line 1329, in _run_raw_task
    self._execute_task_with_callbacks(context)
  File "/home/airflow/.local/lib/python3.7/site-packages/airflow/models/taskinstance.py", line 1455, in _execute_task_with_callbacks
    result = self._execute_task(context, self.task)
  File "/home/airflow/.local/lib/python3.7/site-packages/airflow/models/taskinstance.py", line 1511, in _execute_task
    result = execute_callable(context=context)
  File "/home/airflow/.local/lib/python3.7/site-packages/airflow/operators/python.py", line 174, in execute
    return_value = self.execute_callable()
  File "/home/airflow/.local/lib/python3.7/site-packages/airflow/operators/python.py", line 185, in execute_callable
    return self.python_callable(*self.op_args, **self.op_kwargs)
  File "/opt/airflow/dags/ingest_script.py", line 21, in ingest_callable
    print(csv_file, execution_date)
NameError: name 'csv_file' is not defined
[2022-07-07 18:10:15,359] {taskinstance.py:1277} INFO - Marking task as FAILED. dag_id=LocalIngestionDag, task_id=ingest, execution_date=20210302T060000, start_date=20220707T181015, end_date=20220707T181015
[2022-07-07 18:10:15,372] {standard_task_runner.py:92} ERROR - Failed to execute job 192 for task ingest
Traceback (most recent call last):
  File "/home/airflow/.local/lib/python3.7/site-packages/airflow/task/task_runner/standard_task_runner.py", line 85, in _start_by_fork
    args.func(args, dag=self.dag)
  File "/home/airflow/.local/lib/python3.7/site-packages/airflow/cli/cli_parser.py", line 48, in command
    return func(*args, **kwargs)
  File "/home/airflow/.local/lib/python3.7/site-packages/airflow/utils/cli.py", line 92, in wrapper
    return f(*args, **kwargs)
  File "/home/airflow/.local/lib/python3.7/site-packages/airflow/cli/commands/task_command.py", line 298, in task_run
    _run_task_by_selected_method(args, dag, ti)
  File "/home/airflow/.local/lib/python3.7/site-packages/airflow/cli/commands/task_command.py", line 107, in _run_task_by_selected_method
    _run_raw_task(args, ti)
  File "/home/airflow/.local/lib/python3.7/site-packages/airflow/cli/commands/task_command.py", line 184, in _run_raw_task
    error_file=args.error_file,
  File "/home/airflow/.local/lib/python3.7/site-packages/airflow/utils/session.py", line 70, in wrapper
    return func(*args, session=session, **kwargs)
  File "/home/airflow/.local/lib/python3.7/site-packages/airflow/models/taskinstance.py", line 1329, in _run_raw_task
    self._execute_task_with_callbacks(context)
  File "/home/airflow/.local/lib/python3.7/site-packages/airflow/models/taskinstance.py", line 1455, in _execute_task_with_callbacks
    result = self._execute_task(context, self.task)
  File "/home/airflow/.local/lib/python3.7/site-packages/airflow/models/taskinstance.py", line 1511, in _execute_task
    result = execute_callable(context=context)
  File "/home/airflow/.local/lib/python3.7/site-packages/airflow/operators/python.py", line 174, in execute
    return_value = self.execute_callable()
  File "/home/airflow/.local/lib/python3.7/site-packages/airflow/operators/python.py", line 185, in execute_callable
    return self.python_callable(*self.op_args, **self.op_kwargs)
  File "/opt/airflow/dags/ingest_script.py", line 21, in ingest_callable
    print(csv_file, execution_date)
NameError: name 'csv_file' is not defined
[2022-07-07 18:10:15,417] {local_task_job.py:154} INFO - Task exited with return code 1
[2022-07-07 18:10:15,478] {local_task_job.py:264} INFO - 0 downstream tasks scheduled from follow-on schedule check
