[2022-07-07 18:39:38,478] {taskinstance.py:1032} INFO - Dependencies all met for <TaskInstance: LocalIngestionDag.ingest scheduled__2021-03-02T06:00:00+00:00 [queued]>
[2022-07-07 18:39:38,489] {taskinstance.py:1032} INFO - Dependencies all met for <TaskInstance: LocalIngestionDag.ingest scheduled__2021-03-02T06:00:00+00:00 [queued]>
[2022-07-07 18:39:38,489] {taskinstance.py:1238} INFO - 
--------------------------------------------------------------------------------
[2022-07-07 18:39:38,490] {taskinstance.py:1239} INFO - Starting attempt 18 of 18
[2022-07-07 18:39:38,490] {taskinstance.py:1240} INFO - 
--------------------------------------------------------------------------------
[2022-07-07 18:39:38,502] {taskinstance.py:1259} INFO - Executing <Task(PythonOperator): ingest> on 2021-03-02 06:00:00+00:00
[2022-07-07 18:39:38,509] {standard_task_runner.py:52} INFO - Started process 3061 to run task
[2022-07-07 18:39:38,515] {standard_task_runner.py:76} INFO - Running: ['***', 'tasks', 'run', 'LocalIngestionDag', 'ingest', 'scheduled__2021-03-02T06:00:00+00:00', '--job-id', '199', '--raw', '--subdir', 'DAGS_FOLDER/data_ingestion_local.py', '--cfg-path', '/tmp/tmpj54zu64k', '--error-file', '/tmp/tmpp871360h']
[2022-07-07 18:39:38,517] {standard_task_runner.py:77} INFO - Job 199: Subtask ingest
[2022-07-07 18:39:38,587] {logging_mixin.py:109} INFO - Running <TaskInstance: LocalIngestionDag.ingest scheduled__2021-03-02T06:00:00+00:00 [running]> on host d7995de6702f
[2022-07-07 18:39:38,632] {warnings.py:110} WARNING - /home/***/.local/lib/python3.7/site-packages/***/utils/context.py:152: AirflowContextDeprecationWarning: Accessing 'execution_date' from the template is deprecated and will be removed in a future version. Please use 'data_interval_start' or 'logical_date' instead.
  warnings.warn(_create_deprecation_warning(key, self._deprecation_replacements[key]))

[2022-07-07 18:39:38,653] {taskinstance.py:1426} INFO - Exporting the following env vars:
AIRFLOW_CTX_DAG_OWNER=***
AIRFLOW_CTX_DAG_ID=LocalIngestionDag
AIRFLOW_CTX_TASK_ID=ingest
AIRFLOW_CTX_EXECUTION_DATE=2021-03-02T06:00:00+00:00
AIRFLOW_CTX_DAG_RUN_ID=scheduled__2021-03-02T06:00:00+00:00
[2022-07-07 18:39:38,655] {logging_mixin.py:109} INFO - yellow_taxi_2021_03 /opt/***/output_2021-03.csv 2021-03-02T06:00:00+00:00
[2022-07-07 18:39:38,663] {logging_mixin.py:109} INFO - <sqlalchemy.engine.base.Connection object at 0x7fc495b283d0>
[2022-07-07 18:39:38,663] {logging_mixin.py:109} INFO - connection established successfully, inserting data...
[2022-07-07 18:39:38,664] {warnings.py:110} WARNING - /home/***/.local/lib/python3.7/site-packages/***/operators/python.py:185: FutureWarning: The error_bad_lines argument has been deprecated and will be removed in a future version.


  return self.python_callable(*self.op_args, **self.op_kwargs)

[2022-07-07 18:39:38,675] {logging_mixin.py:109} WARNING - b'Skipping line 19: expected 2 fields, saw 3\nSkipping line 25: expected 2 fields, saw 3\nSkipping line 62: expected 2 fields, saw 3\nSkipping line 63: expected 2 fields, saw 3\nSkipping line 139: expected 2 fields, saw 3\nSkipping line 161: expected 2 fields, saw 5\nSkipping line 167: expected 2 fields, saw 3\nSkipping line 193: expected 2 fields, saw 3\nSkipping line 214: expected 2 fields, saw 3\nSkipping line 219: expected 2 fields, saw 3\nSkipping line 220: expected 2 fields, saw 4\n'
[2022-07-07 18:39:38,675] {taskinstance.py:1700} ERROR - Task failed with exception
Traceback (most recent call last):
  File "/home/airflow/.local/lib/python3.7/site-packages/airflow/models/taskinstance.py", line 1329, in _run_raw_task
    self._execute_task_with_callbacks(context)
  File "/home/airflow/.local/lib/python3.7/site-packages/airflow/models/taskinstance.py", line 1455, in _execute_task_with_callbacks
    result = self._execute_task(context, self.task)
  File "/home/airflow/.local/lib/python3.7/site-packages/airflow/models/taskinstance.py", line 1511, in _execute_task
    result = execute_callable(context=context)
  File "/home/airflow/.local/lib/python3.7/site-packages/airflow/operators/python.py", line 174, in execute
    return_value = self.execute_callable()
  File "/home/airflow/.local/lib/python3.7/site-packages/airflow/operators/python.py", line 185, in execute_callable
    return self.python_callable(*self.op_args, **self.op_kwargs)
  File "/opt/airflow/dags/ingest_script.py", line 39, in ingest_callable
    df = next(df_iter)
  File "/home/airflow/.local/lib/python3.7/site-packages/pandas/io/parsers/readers.py", line 1024, in __next__
    return self.get_chunk()
  File "/home/airflow/.local/lib/python3.7/site-packages/pandas/io/parsers/readers.py", line 1074, in get_chunk
    return self.read(nrows=size)
  File "/home/airflow/.local/lib/python3.7/site-packages/pandas/io/parsers/readers.py", line 1047, in read
    index, columns, col_dict = self._engine.read(nrows)
  File "/home/airflow/.local/lib/python3.7/site-packages/pandas/io/parsers/c_parser_wrapper.py", line 224, in read
    chunks = self._reader.read_low_memory(nrows)
  File "pandas/_libs/parsers.pyx", line 813, in pandas._libs.parsers.TextReader.read_low_memory
  File "pandas/_libs/parsers.pyx", line 857, in pandas._libs.parsers.TextReader._read_rows
  File "pandas/_libs/parsers.pyx", line 843, in pandas._libs.parsers.TextReader._tokenize_rows
  File "pandas/_libs/parsers.pyx", line 1925, in pandas._libs.parsers.raise_parser_error
pandas.errors.ParserError: Error tokenizing data. C error: Buffer overflow caught - possible malformed input file.

[2022-07-07 18:39:38,690] {taskinstance.py:1277} INFO - Marking task as FAILED. dag_id=LocalIngestionDag, task_id=ingest, execution_date=20210302T060000, start_date=20220707T183938, end_date=20220707T183938
[2022-07-07 18:39:38,706] {standard_task_runner.py:92} ERROR - Failed to execute job 199 for task ingest
Traceback (most recent call last):
  File "/home/airflow/.local/lib/python3.7/site-packages/airflow/task/task_runner/standard_task_runner.py", line 85, in _start_by_fork
    args.func(args, dag=self.dag)
  File "/home/airflow/.local/lib/python3.7/site-packages/airflow/cli/cli_parser.py", line 48, in command
    return func(*args, **kwargs)
  File "/home/airflow/.local/lib/python3.7/site-packages/airflow/utils/cli.py", line 92, in wrapper
    return f(*args, **kwargs)
  File "/home/airflow/.local/lib/python3.7/site-packages/airflow/cli/commands/task_command.py", line 298, in task_run
    _run_task_by_selected_method(args, dag, ti)
  File "/home/airflow/.local/lib/python3.7/site-packages/airflow/cli/commands/task_command.py", line 107, in _run_task_by_selected_method
    _run_raw_task(args, ti)
  File "/home/airflow/.local/lib/python3.7/site-packages/airflow/cli/commands/task_command.py", line 184, in _run_raw_task
    error_file=args.error_file,
  File "/home/airflow/.local/lib/python3.7/site-packages/airflow/utils/session.py", line 70, in wrapper
    return func(*args, session=session, **kwargs)
  File "/home/airflow/.local/lib/python3.7/site-packages/airflow/models/taskinstance.py", line 1329, in _run_raw_task
    self._execute_task_with_callbacks(context)
  File "/home/airflow/.local/lib/python3.7/site-packages/airflow/models/taskinstance.py", line 1455, in _execute_task_with_callbacks
    result = self._execute_task(context, self.task)
  File "/home/airflow/.local/lib/python3.7/site-packages/airflow/models/taskinstance.py", line 1511, in _execute_task
    result = execute_callable(context=context)
  File "/home/airflow/.local/lib/python3.7/site-packages/airflow/operators/python.py", line 174, in execute
    return_value = self.execute_callable()
  File "/home/airflow/.local/lib/python3.7/site-packages/airflow/operators/python.py", line 185, in execute_callable
    return self.python_callable(*self.op_args, **self.op_kwargs)
  File "/opt/airflow/dags/ingest_script.py", line 39, in ingest_callable
    df = next(df_iter)
  File "/home/airflow/.local/lib/python3.7/site-packages/pandas/io/parsers/readers.py", line 1024, in __next__
    return self.get_chunk()
  File "/home/airflow/.local/lib/python3.7/site-packages/pandas/io/parsers/readers.py", line 1074, in get_chunk
    return self.read(nrows=size)
  File "/home/airflow/.local/lib/python3.7/site-packages/pandas/io/parsers/readers.py", line 1047, in read
    index, columns, col_dict = self._engine.read(nrows)
  File "/home/airflow/.local/lib/python3.7/site-packages/pandas/io/parsers/c_parser_wrapper.py", line 224, in read
    chunks = self._reader.read_low_memory(nrows)
  File "pandas/_libs/parsers.pyx", line 813, in pandas._libs.parsers.TextReader.read_low_memory
  File "pandas/_libs/parsers.pyx", line 857, in pandas._libs.parsers.TextReader._read_rows
  File "pandas/_libs/parsers.pyx", line 843, in pandas._libs.parsers.TextReader._tokenize_rows
  File "pandas/_libs/parsers.pyx", line 1925, in pandas._libs.parsers.raise_parser_error
pandas.errors.ParserError: Error tokenizing data. C error: Buffer overflow caught - possible malformed input file.

[2022-07-07 18:39:38,728] {local_task_job.py:154} INFO - Task exited with return code 1
[2022-07-07 18:39:38,761] {local_task_job.py:264} INFO - 0 downstream tasks scheduled from follow-on schedule check
