[2022-07-07 15:59:22,656] {taskinstance.py:1032} INFO - Dependencies all met for <TaskInstance: LocalIngestionDag.convert_to_csv scheduled__2022-06-02T06:00:00+00:00 [queued]>
[2022-07-07 15:59:22,671] {taskinstance.py:1032} INFO - Dependencies all met for <TaskInstance: LocalIngestionDag.convert_to_csv scheduled__2022-06-02T06:00:00+00:00 [queued]>
[2022-07-07 15:59:22,671] {taskinstance.py:1238} INFO - 
--------------------------------------------------------------------------------
[2022-07-07 15:59:22,671] {taskinstance.py:1239} INFO - Starting attempt 1 of 1
[2022-07-07 15:59:22,671] {taskinstance.py:1240} INFO - 
--------------------------------------------------------------------------------
[2022-07-07 15:59:22,690] {taskinstance.py:1259} INFO - Executing <Task(PythonOperator): convert_to_csv> on 2022-06-02 06:00:00+00:00
[2022-07-07 15:59:22,697] {standard_task_runner.py:52} INFO - Started process 2440 to run task
[2022-07-07 15:59:22,704] {standard_task_runner.py:76} INFO - Running: ['***', 'tasks', 'run', 'LocalIngestionDag', 'convert_to_csv', 'scheduled__2022-06-02T06:00:00+00:00', '--job-id', '164', '--raw', '--subdir', 'DAGS_FOLDER/data_ingestion_local.py', '--cfg-path', '/tmp/tmp94dbz9wj', '--error-file', '/tmp/tmpfrtz28_y']
[2022-07-07 15:59:22,705] {standard_task_runner.py:77} INFO - Job 164: Subtask convert_to_csv
[2022-07-07 15:59:22,779] {logging_mixin.py:109} INFO - Running <TaskInstance: LocalIngestionDag.convert_to_csv scheduled__2022-06-02T06:00:00+00:00 [running]> on host d7995de6702f
[2022-07-07 15:59:22,825] {warnings.py:110} WARNING - /home/***/.local/lib/python3.7/site-packages/***/utils/context.py:152: AirflowContextDeprecationWarning: Accessing 'execution_date' from the template is deprecated and will be removed in a future version. Please use 'data_interval_start' or 'logical_date' instead.
  warnings.warn(_create_deprecation_warning(key, self._deprecation_replacements[key]))

[2022-07-07 15:59:22,849] {taskinstance.py:1426} INFO - Exporting the following env vars:
AIRFLOW_CTX_DAG_OWNER=***
AIRFLOW_CTX_DAG_ID=LocalIngestionDag
AIRFLOW_CTX_TASK_ID=convert_to_csv
AIRFLOW_CTX_EXECUTION_DATE=2022-06-02T06:00:00+00:00
AIRFLOW_CTX_DAG_RUN_ID=scheduled__2022-06-02T06:00:00+00:00
[2022-07-07 15:59:22,864] {taskinstance.py:1700} ERROR - Task failed with exception
Traceback (most recent call last):
  File "/home/airflow/.local/lib/python3.7/site-packages/airflow/models/taskinstance.py", line 1329, in _run_raw_task
    self._execute_task_with_callbacks(context)
  File "/home/airflow/.local/lib/python3.7/site-packages/airflow/models/taskinstance.py", line 1455, in _execute_task_with_callbacks
    result = self._execute_task(context, self.task)
  File "/home/airflow/.local/lib/python3.7/site-packages/airflow/models/taskinstance.py", line 1511, in _execute_task
    result = execute_callable(context=context)
  File "/home/airflow/.local/lib/python3.7/site-packages/airflow/operators/python.py", line 174, in execute
    return_value = self.execute_callable()
  File "/home/airflow/.local/lib/python3.7/site-packages/airflow/operators/python.py", line 185, in execute_callable
    return self.python_callable(*self.op_args, **self.op_kwargs)
  File "/opt/airflow/dags/ingest_script.py", line 14, in format_to_csv
    table = pq.read_table(src_file)
  File "/home/airflow/.local/lib/python3.7/site-packages/pyarrow/parquet.py", line 1869, in read_table
    coerce_int96_timestamp_unit=coerce_int96_timestamp_unit
  File "/home/airflow/.local/lib/python3.7/site-packages/pyarrow/parquet.py", line 1679, in __init__
    [fragment], schema=fragment.physical_schema,
  File "pyarrow/_dataset.pyx", line 952, in pyarrow._dataset.Fragment.physical_schema.__get__
  File "pyarrow/error.pxi", line 143, in pyarrow.lib.pyarrow_internal_check_status
  File "pyarrow/error.pxi", line 99, in pyarrow.lib.check_status
pyarrow.lib.ArrowInvalid: Could not open Parquet input source '/opt/***/output_2022-06.parquet': Parquet magic bytes not found in footer. Either the file is corrupted or this is not a parquet file.
[2022-07-07 15:59:22,882] {taskinstance.py:1277} INFO - Marking task as FAILED. dag_id=LocalIngestionDag, task_id=convert_to_csv, execution_date=20220602T060000, start_date=20220707T155922, end_date=20220707T155922
[2022-07-07 15:59:22,896] {standard_task_runner.py:92} ERROR - Failed to execute job 164 for task convert_to_csv
Traceback (most recent call last):
  File "/home/airflow/.local/lib/python3.7/site-packages/airflow/task/task_runner/standard_task_runner.py", line 85, in _start_by_fork
    args.func(args, dag=self.dag)
  File "/home/airflow/.local/lib/python3.7/site-packages/airflow/cli/cli_parser.py", line 48, in command
    return func(*args, **kwargs)
  File "/home/airflow/.local/lib/python3.7/site-packages/airflow/utils/cli.py", line 92, in wrapper
    return f(*args, **kwargs)
  File "/home/airflow/.local/lib/python3.7/site-packages/airflow/cli/commands/task_command.py", line 298, in task_run
    _run_task_by_selected_method(args, dag, ti)
  File "/home/airflow/.local/lib/python3.7/site-packages/airflow/cli/commands/task_command.py", line 107, in _run_task_by_selected_method
    _run_raw_task(args, ti)
  File "/home/airflow/.local/lib/python3.7/site-packages/airflow/cli/commands/task_command.py", line 184, in _run_raw_task
    error_file=args.error_file,
  File "/home/airflow/.local/lib/python3.7/site-packages/airflow/utils/session.py", line 70, in wrapper
    return func(*args, session=session, **kwargs)
  File "/home/airflow/.local/lib/python3.7/site-packages/airflow/models/taskinstance.py", line 1329, in _run_raw_task
    self._execute_task_with_callbacks(context)
  File "/home/airflow/.local/lib/python3.7/site-packages/airflow/models/taskinstance.py", line 1455, in _execute_task_with_callbacks
    result = self._execute_task(context, self.task)
  File "/home/airflow/.local/lib/python3.7/site-packages/airflow/models/taskinstance.py", line 1511, in _execute_task
    result = execute_callable(context=context)
  File "/home/airflow/.local/lib/python3.7/site-packages/airflow/operators/python.py", line 174, in execute
    return_value = self.execute_callable()
  File "/home/airflow/.local/lib/python3.7/site-packages/airflow/operators/python.py", line 185, in execute_callable
    return self.python_callable(*self.op_args, **self.op_kwargs)
  File "/opt/airflow/dags/ingest_script.py", line 14, in format_to_csv
    table = pq.read_table(src_file)
  File "/home/airflow/.local/lib/python3.7/site-packages/pyarrow/parquet.py", line 1869, in read_table
    coerce_int96_timestamp_unit=coerce_int96_timestamp_unit
  File "/home/airflow/.local/lib/python3.7/site-packages/pyarrow/parquet.py", line 1679, in __init__
    [fragment], schema=fragment.physical_schema,
  File "pyarrow/_dataset.pyx", line 952, in pyarrow._dataset.Fragment.physical_schema.__get__
  File "pyarrow/error.pxi", line 143, in pyarrow.lib.pyarrow_internal_check_status
  File "pyarrow/error.pxi", line 99, in pyarrow.lib.check_status
pyarrow.lib.ArrowInvalid: Could not open Parquet input source '/opt/***/output_2022-06.parquet': Parquet magic bytes not found in footer. Either the file is corrupted or this is not a parquet file.
[2022-07-07 15:59:22,917] {local_task_job.py:154} INFO - Task exited with return code 1
[2022-07-07 15:59:22,969] {local_task_job.py:264} INFO - 0 downstream tasks scheduled from follow-on schedule check
